<?xml version="1.0" encoding="utf-8"?>
<!-- =================================================================================== -->
<!-- |    This document was autogenerated by xacro from wam_7dof_wam_bhand.urdf.xacro  | -->
<!-- |    EDITING THIS FILE BY HAND IS NOT RECOMMENDED                                 | -->
<!-- =================================================================================== -->
<robot name="wam" xmlns:controller="http://playerstage.sourceforge.net/gazebo/xmlschema/#controller"   xmlns:xacro="http://www.ros.org/wiki/xacro">

  <material name="WAMGrey">
    <color rgba="0.7 0.7 0.7 1.0"/>
  </material>

  <!-- <xacro:include filename="$(find barrett_model)/robots/test_robot.urdf.xacro" /> -->
	<xacro:include filename="$(find barrett_model)/robots/mobile_chassis.urdf.xacro" />
  <xacro:mrobot_body/>

  <joint name="wam/wam_fixed_joint" type="fixed">
    <parent link="base_footprint"/>
    <child link="wam/base_link"/>
    <origin rpy="0 0 0" xyz="0.0 0.0 0.03"/>
  </joint>
  <gazebo reference="wam/wam_fixed_joint">
    <provideFeedback>true</provideFeedback>
    <implicitSpringDamper>true</implicitSpringDamper>
  </gazebo>


  <link name="wam/base_link">
    <inertial>
      <origin xyz="0 0 0"/>
      <mass value="10"/>
      <inertia ixx="0.1" ixy="0" ixz="0" iyy="0.1" iyz="0" izz="0.1"/>
    </inertial>
    <visual>
      <material name="WAMGrey">
        <color rgba="0.7 0.7 0.7 0.0"/>
      </material>
      <geometry>
        <mesh filename="package://barrett_model/models/sw_meshes/base_link_fine.stl"/>
      </geometry>
    </visual>
    <collision>
      <geometry>
        <mesh filename="package://barrett_model/models/sw_meshes/base_link_convex.dae"/>
      </geometry>
    </collision>
  </link>
  <joint name="wam/base_yaw_joint" type="revolute">
    <parent link="wam/base_link"/>
    <child link="wam/shoulder_yaw_link"/>
    <origin rpy="0 0 0" xyz="0 0 0.346"/>
    <axis xyz="0 0 1"/>
    <limit effort="60" lower="-2.6000169867" upper="2.6000169867" velocity="2.0"/>
    <dynamics damping="1.98" friction="0"/>
  </joint>
  <gazebo reference="wam/base_yaw_joint">
    <provideFeedback>true</provideFeedback>
    <implicitSpringDamper>true</implicitSpringDamper>
    <!--<kp>0.0</kp>[> CFM <]-->
    <!--<kd>0.0</kd>[> ERP <]-->
    <!--<cfmDamping>true</cfmDamping>-->
    <!--<dynamics damping="5.5" friction="1"/>-->
  </gazebo>





  <link name="wam/shoulder_yaw_link">
    <inertial>
      <origin xyz="-.00443422 -.00066489 -0.1289039 "/>
      <mass value="5.0"/>
      <inertia ixx=".13488033" ixy="-0.00012485" ixz="0.00213041" iyy=".09046330" iyz="-.00068555" izz=".11328369"/>
    </inertial>
    <visual>
      <material name="WAMGrey">
        <color rgba="0.7 0.7 0.7 1.0"/>
      </material>
      <geometry>
        <mesh filename="package://barrett_model/models/sw_meshes/shoulder_link_fine.stl"/>
      </geometry>
    </visual>
    <collision>
      <geometry>
        <mesh filename="package://barrett_model/models/sw_meshes/shoulder_link_convex_decomposition.dae"/>
      </geometry>
    </collision>
  </link>
  <joint name="wam/shoulder_pitch_joint" type="revolute">
    <parent link="wam/shoulder_yaw_link"/>
    <child link="wam/shoulder_pitch_link"/>
    <origin rpy="-1.57079632679 0 0" xyz="0 0 0"/>
    <axis xyz="0 0 1"/>
    <limit effort="60" lower="-1.98499786488" upper="1.98499786488" velocity="2.0"/>
    <dynamics damping="0.55" friction="0"/>
  </joint>
  <gazebo reference="wam/shoulder_pitch_joint">
    <provideFeedback>true</provideFeedback>
    <implicitSpringDamper>true</implicitSpringDamper>
    <!--<kp>0.0</kp>[> CFM <]-->
    <!--<kd>0.0</kd>[> ERP <]-->
    <!--<cfmDamping>true</cfmDamping>-->
    <!--<dynamics damping="5.5" friction="1"/>-->
  </gazebo>
  
  


  <link name="wam/shoulder_pitch_link">
    <visual>
      <material name="WAMGrey">
        <color rgba="0.7 0.7 0.7 1.0"/>
      </material>
      <geometry>
        <mesh filename="package://barrett_model/models/sw_meshes/shoulder_pitch_link_fine.stl"/>
      </geometry>
    </visual>
    <inertial>
      <origin xyz="-.00236981 -.01542114 .03105614 "/>
      <mass value="3.87493756"/>
      <inertia ixx="0.02140958" ixy="-0.00002461" ixz="0.00027172" iyy="0.015589060" iyz="0.0018192" izz="0.01377875"/>
    </inertial>
    <collision>
      <geometry>
        <mesh filename="package://barrett_model/models/sw_meshes/shoulder_pitch_link_convex.dae"/>
      </geometry>
    </collision>
  </link>
  <joint name="wam/shoulder_yaw_joint" type="revolute">
    <parent link="wam/shoulder_pitch_link"/>
    <child link="wam/upper_arm_link"/>
    <origin rpy="1.57079632679 0 0" xyz="0 0 0"/>
    <axis xyz="0 0 1"/>
    <!-- <limit effort="45" lower="-2.79999681239" upper="2.79999681239" velocity="2.0"/> -->
    <limit effort="45" lower="-3.9999681239" upper="3.79999681239" velocity="2.0"/>
    <!-- this is joint 3 -->
    <dynamics damping="1.65" friction="0"/>
  </joint>
  <gazebo reference="wam/shoulder_yaw_joint">
    <provideFeedback>true</provideFeedback>
    <implicitSpringDamper>true</implicitSpringDamper>
    <!--<kp>0.0</kp>[> CFM <]-->
    <!--<kd>0.0</kd>[> ERP <]-->
    <!--<cfmDamping>true</cfmDamping>-->
    <!--<dynamics damping="5.5" friction="1"/>-->
  </gazebo>
  
  




  <link name="wam/upper_arm_link">
    <inertial>
      <origin xyz="0.00683258580000000 0.000033090000000 0.392492300000000"/>
      <mass value="2.20228141"/>
      <inertia ixx=".05911077" ixy="-0.00000738" ixz="-0.00249612" iyy="0.05927043" iyz="0.00001767" izz="0.0032455"/>
    </inertial>
    <visual>
      <material name="WAMGrey">
        <color rgba="0.7 0.7 0.7 1.0"/>
      </material>
      <geometry>
        <mesh filename="package://barrett_model/models/sw_meshes/upper_arm_link_fine.stl"/>
      </geometry>
    </visual>
    <collision>
      <geometry>
        <mesh filename="package://barrett_model/models/sw_meshes/upper_arm_link_convex_decomposition.dae"/>
      </geometry>
    </collision>
  </link>
  <joint name="wam/elbow_pitch_joint" type="revolute">
    <parent link="wam/upper_arm_link"/>
    <child link="wam/forearm_link"/>
    <origin rpy="-1.57079632679 0 0" xyz="0.045 0 0.55"/>
    <axis xyz="0 0 1"/>
    <limit effort="30" lower="-0.900013935376" upper="3.14159265359" velocity="2.00"/>
    <dynamics damping="0.88" friction="0"/>
  </joint>
  <gazebo reference="wam/elbow_pitch_joint">
    <provideFeedback>true</provideFeedback>
    <implicitSpringDamper>true</implicitSpringDamper>
    <!--<kp>0.0</kp>[> CFM <]-->
    <!--<kd>0.0</kd>[> ERP <]-->
    <!--<cfmDamping>true</cfmDamping>-->
    <!--<dynamics damping="5.5" friction="1"/>-->
  </gazebo>
  
  



  <link name="wam/forearm_link">
    <inertial>
      <mass value="0.50016804"/>
      <origin rpy="0 0 0" xyz="-0.04001488 -.14271662 -.00022942 "/>
      <inertia ixx="0.01491672" ixy="0.001506040000000" ixz="0.000017410000000" iyy="0.002944630000000" iyz="0.000021090000000" izz="0.014829880000000"/>
    </inertial>
    <visual>
      <material name="WAMGrey">
        <color rgba="0.7 0.7 0.7 1.0"/>
      </material>
      <geometry>
        <mesh filename="package://barrett_model/models/sw_meshes/elbow_link_fine.stl"/>
      </geometry>
    </visual>
    <collision>
      <geometry>
        <mesh filename="package://barrett_model/models/sw_meshes/elbow_link_convex.dae"/>
      </geometry>
    </collision>
    <visual>
      <material name="WAMGrey">
        <color rgba="0.7 0.7 0.7 1.0"/>
      </material>
      <origin rpy="1.57079632679 0 0" xyz="-0.045 -0.0730 0"/>
      <geometry>
        <mesh filename="package://barrett_model/models/sw_meshes/forearm_link_fine.stl"/>
      </geometry>
    </visual>
    <collision>
      <origin rpy="1.57079632679 0 0" xyz="-0.045 -0.0730 0"/>
      <geometry>
        <mesh filename="package://barrett_model/models/sw_meshes/forearm_link_convex_decomposition.dae"/>
      </geometry>
    </collision>
  </link>
  <joint name="wam/wrist_yaw_joint" type="revolute">
    <parent link="wam/forearm_link"/>
    <child link="wam/wrist_yaw_link"/>
    <origin rpy="1.57079632679 0 0" xyz="-0.045 -0.3 0"/>
    <axis xyz="0 0 1"/>
    <!-- <limit effort="10" lower="-4.55000354678" upper="1.25000481028" velocity="2.0"/> -->
    <limit effort="10" lower="-4.55000354678" upper="2.25000481028" velocity="2.0"/>
    <!-- this is joint 5 -->
    <dynamics damping="0.55" friction="0"/>
  </joint>
  <gazebo reference="wam/wrist_yaw_joint">
    <provideFeedback>true</provideFeedback>
    <implicitSpringDamper>true</implicitSpringDamper>
    <!--<kp>0.0</kp>[> CFM <]-->
    <!--<kd>0.0</kd>[> ERP <]-->
    <!--<cfmDamping>true</cfmDamping>-->
    <!--<dynamics damping="5.5" friction="1"/>-->
  </gazebo>
  




  <link name="wam/wrist_yaw_link">
    <inertial>
      <origin xyz="0.00008921 0.00435824 -0.00511217 "/>
      <mass value="1.05376019"/>
      <inertia ixx="0.00005029" ixy="0.00000020" ixz="0.00007582" iyy="0.00007582" iyz="-0.00000359" izz="0.00006270"/>
    </inertial>
    <visual>
      <material name="WAMGrey">
        <color rgba="0.7 0.7 0.7 1.0"/>
      </material>
      <origin rpy="0 0 0" xyz="0 0 0"/>
      <geometry>
        <mesh filename="package://barrett_model/models/sw_meshes/wrist_yaw_link_fine.stl"/>
      </geometry>
    </visual>
    <collision>
      <origin rpy="0 0 0" xyz="0 0 0"/>
      <geometry>
        <mesh filename="package://barrett_model/models/sw_meshes/wrist_yaw_link_convex_decomposition.dae"/>
      </geometry>
    </collision>
  </link>
  <joint name="wam/wrist_pitch_joint" type="revolute">
    <parent link="wam/wrist_yaw_link"/>
    <child link="wam/wrist_pitch_link"/>
    <origin rpy="-1.57079632679 0 0" xyz="0 0 0"/>
    <axis xyz="0 0 1"/>
    <limit effort="10" lower="-1.57079632679" upper="1.57079632679" velocity="2.00"/>
    <dynamics damping="0.11" friction="0"/>
  </joint>
  <gazebo reference="wam/wrist_pitch_joint">
    <provideFeedback>true</provideFeedback>
    <implicitSpringDamper>true</implicitSpringDamper>
    <!--<kp>0.0</kp>[> CFM <]-->
    <!--<kd>0.0</kd>[> ERP <]-->
    <!--<cfmDamping>true</cfmDamping>-->
    <!--<dynamics damping="5.5" friction="1"/>-->
  </gazebo>
  
  



  <link name="wam/wrist_pitch_link">
    <inertial>
      <origin rpy="0 0 0" xyz="-0.00012262 -0.02468336 -0.01703194 "/>
      <mass value="0.51797364"/>
      <inertia ixx="0.00055516" ixy="0.00000061" ixz="-0.00000074" iyy="0.00024367" iyz="-0.00004590" izz="0.00045358"/>
    </inertial>
    <visual>
      <material name="WAMGrey">
        <color rgba="0.7 0.7 0.7 1.0"/>
      </material>
      <geometry>
        <mesh filename="package://barrett_model/models/sw_meshes/wrist_pitch_link_fine.stl"/>
      </geometry>
    </visual>
    <collision>
      <geometry>
        <mesh filename="package://barrett_model/models/sw_meshes/wrist_pitch_link_convex_decomposition.dae"/>
      </geometry>
    </collision>
  </link>
  <joint name="wam/palm_yaw_joint" type="revolute">
    <parent link="wam/wrist_pitch_link"/>
    <child link="wam/wrist_palm_link"/>
    <origin rpy="1.57079632679 0 0" xyz="0 0 0"/>
    <axis xyz="0 0 1"/>
    <limit effort="10" lower="-3.00004645125" upper="3.00004645125" velocity="2.00"/>
    <!-- 2.95 is a limit taken in from 3 due to saftey and differences between arms. -->
    <dynamics damping="0.11" friction="0"/>
  </joint>
  <gazebo reference="wam/palm_yaw_joint">
    <provideFeedback>true</provideFeedback>
    <implicitSpringDamper>true</implicitSpringDamper>
    <!--<kp>0.0</kp>[> CFM <]-->
    <!--<kd>0.0</kd>[> ERP <]-->
    <!--<cfmDamping>true</cfmDamping>-->
    <!--<dynamics damping="5.5" friction="1"/>-->
  </gazebo>
  <transmission name="wam/palm_yaw_trans">
    <type>transmission_interface/SimpleTransmission</type>
    <joint name="wam/palm_yaw_joint">
      <hardwareInterface>hardware_interface/VelocityJointInterface</hardwareInterface>
    </joint>
    <actuator name="wam/palm_yaw_motor">
      <mechanicalReduction>1</mechanicalReduction>
    </actuator>
  </transmission>
  <link name="wam/wrist_palm_link">
    <inertial>
      <origin rpy="0 0 0" xyz="0.0 0.0 0.055"/>
      <mass value="0.08286134"/>
      <inertia ixx="0.00010859" ixy="0.00000000" ixz="-0.00000000" iyy="0.00020683" iyz="-0.0000000" izz="0.00010851"/>
    </inertial>
    <visual>
      <material name="WAMGrey">
        <color rgba="0.7 0.7 0.7 1.0"/>
      </material>
      <origin rpy="0 0 0" xyz="0 0 0"/>
      <geometry>
        <mesh filename="package://barrett_model/models/sw_meshes/wrist_palm_link_fine.stl"/>
      </geometry>
    </visual>
    <collision>
      <origin rpy="0 0 0" xyz="0 0 0"/>
      <geometry>
        <mesh filename="package://barrett_model/models/sw_meshes/wrist_palm_link_convex.dae"/>
      </geometry>
    </collision>
  </link>
  <joint name="wam/wrist_palm_stump_joint" type="fixed">
    <parent link="wam/wrist_palm_link"/>
    <child link="wam/wrist_palm_stump_link"/>
    <origin rpy="0 0 0" xyz="0 0 0.06"/>
  </joint>
  <link name="wam/wrist_palm_stump_link">
    <inertial>
      <mass value="0.000001"/>
      <inertia ixx="0.0000001" ixy="0.0" ixz="0.0" iyy="0.0000001" iyz="0.0" izz="0.0000001"/>
    </inertial>
  </link>

  <!-- macro sensor_kinect -->
  <xacro:include filename="$(find barrett_model)/models/kinect.urdf.xacro"/>
  <xacro:sensor_kinect parent="wam/wrist_palm_stump_link" cam_px_input="0.02" cam_pz_input="0.07"/>

  <!-- Transmissions for ROS Control -->
  <xacro:macro name="transmission_block" params="joint_name">
      <transmission name="wam/${joint_name}_trans">
          <type>transmission_interface/SimpleTransmission</type>
          <joint name="wam/${joint_name}_joint">
              <hardwareInterface>hardware_interface/PositionJointInterface</hardwareInterface>
          </joint>
          <actuator name="wam/${joint_name}_motor">
              <hardwareInterface>hardware_interface/PositionJointInterface</hardwareInterface>
              <mechanicalReduction>1</mechanicalReduction>
          </actuator>
      </transmission>
  </xacro:macro>
    
  <xacro:transmission_block joint_name="base_yaw"/>
  <xacro:transmission_block joint_name="shoulder_pitch"/>
  <xacro:transmission_block joint_name="shoulder_yaw"/>
  <xacro:transmission_block joint_name="elbow_pitch"/>
  <xacro:transmission_block joint_name="wrist_yaw"/>
  <xacro:transmission_block joint_name="wrist_pitch"/>
  <xacro:transmission_block joint_name="palm_yaw"/>


  <gazebo>
    <plugin name="gazebo_ros_control" filename="libgazebo_ros_control.so">
        <robotNamespace>/arm</robotNamespace>
        <legacyModeNS>true</legacyModeNS>
    </plugin>
  </gazebo>
  

</robot>

