<sdf version='1.7'>
  <world name='default'>
    <light name='sun' type='directional'>
      <cast_shadows>1</cast_shadows>
      <pose>0 0 10 0 -0 0</pose>
      <diffuse>0.8 0.8 0.8 1</diffuse>
      <specular>0.2 0.2 0.2 1</specular>
      <attenuation>
        <range>1000</range>
        <constant>0.9</constant>
        <linear>0.01</linear>
        <quadratic>0.001</quadratic>
      </attenuation>
      <direction>-0.5 0.1 -0.9</direction>
      <spot>
        <inner_angle>0</inner_angle>
        <outer_angle>0</outer_angle>
        <falloff>0</falloff>
      </spot>
    </light>
    <model name='ground_plane'>
      <static>1</static>
      <link name='link'>
        <collision name='collision'>
          <geometry>
            <plane>
              <normal>0 0 1</normal>
              <size>100 100</size>
            </plane>
          </geometry>
          <surface>
            <friction>
              <ode>
                <mu>100</mu>
                <mu2>50</mu2>
              </ode>
              <torsional>
                <ode/>
              </torsional>
            </friction>
            <contact>
              <ode/>
            </contact>
            <bounce/>
          </surface>
          <max_contacts>10</max_contacts>
        </collision>
        <visual name='visual'>
          <cast_shadows>0</cast_shadows>
          <geometry>
            <plane>
              <normal>0 0 1</normal>
              <size>100 100</size>
            </plane>
          </geometry>
          <material>
            <script>
              <uri>file://media/materials/scripts/gazebo.material</uri>
              <name>Gazebo/Grey</name>
            </script>
          </material>
        </visual>
        <self_collide>0</self_collide>
        <enable_wind>0</enable_wind>
        <kinematic>0</kinematic>
      </link>
    </model>
    <gravity>0 0 -9.8</gravity>
    <magnetic_field>6e-06 2.3e-05 -4.2e-05</magnetic_field>
    <atmosphere type='adiabatic'/>
    <physics name='default_physics' default='0' type='ode'>
      <max_step_size>0.001</max_step_size>
      <real_time_factor>1</real_time_factor>
      <real_time_update_rate>1000</real_time_update_rate>
    </physics>
    <scene>
      <ambient>0.4 0.4 0.4 1</ambient>
      <background>0.7 0.7 0.7 1</background>
      <shadows>1</shadows>
    </scene>
    <wind/>
    <spherical_coordinates>
      <surface_model>EARTH_WGS84</surface_model>
      <latitude_deg>0</latitude_deg>
      <longitude_deg>0</longitude_deg>
      <elevation>0</elevation>
      <heading_deg>0</heading_deg>
    </spherical_coordinates>
    <state world_name='default'>
      <sim_time>21544 687000000</sim_time>
      <real_time>117 591288196</real_time>
      <wall_time>1741118987 377212840</wall_time>
      <iterations>116630</iterations>
      <model name='ground_plane'>
        <pose>0 0 0 0 -0 0</pose>
        <scale>1 1 1</scale>
        <link name='link'>
          <pose>0 0 0 0 -0 0</pose>
          <velocity>0 0 0 0 -0 0</velocity>
          <acceleration>0 0 0 0 -0 0</acceleration>
          <wrench>0 0 0 0 -0 0</wrench>
        </link>
      </model>
      <model name='mrobot'>
        <pose>-0.005348 -0.00079 -1.1e-05 -3.1e-05 7.8e-05 0.074925</pose>
        <scale>1 1 1</scale>
        <link name='wam/base_link'>
          <pose>-0.005348 -0.00079 -1.1e-05 -3.1e-05 7.8e-05 0.074925</pose>
          <velocity>-0.000275 3e-06 -0.000887 0.016399 0.096689 -2.8e-05</velocity>
          <acceleration>-0.657784 0.037626 5.05727 -0.535019 1.11508 2.22004</acceleration>
          <wrench>-657.784 37.6264 5057.27 0 -0 0</wrench>
        </link>
        <link name='wam/forearm_link'>
          <pose>0.039698 0.002782 0.895968 -1.57102 -0.000883 0.075031</pose>
          <velocity>0.023913 0.006714 -0.001172 0.062019 -0.949787 0.021843</velocity>
          <acceleration>-9.21217 -8.15627 11.7142 -2.48852 0.793282 -0.741243</acceleration>
          <wrench>-4.60763 -4.07951 5.85905 0 -0 0</wrench>
        </link>
        <link name='wam/shoulder_pitch_link'>
          <pose>-0.0053 -0.000769 0.345981 -1.57087 0.000263 0.074932</pose>
          <velocity>0.032642 -0.002303 -0.001821 0.009788 -0.013435 0.045498</velocity>
          <acceleration>110.293 -20.3057 3.07603 1.30157 0.828387 -0.502614</acceleration>
          <wrench>427.378 -78.6833 11.9194 0 -0 0</wrench>
        </link>
        <link name='wam/shoulder_yaw_link'>
          <pose>-0.005306 -0.000774 0.345989 -8.8e-05 0.000144 0.074926</pose>
          <velocity>0.032878 -0.003412 -0.000912 0.001693 0.094556 0.045378</velocity>
          <acceleration>73.1058 -17.6304 6.44619 -0.128381 1.328 -1.54705</acceleration>
          <wrench>365.529 -88.1521 32.2309 0 -0 0</wrench>
        </link>
        <link name='wam/upper_arm_link'>
          <pose>-0.005301 -0.00074 0.34598 -0.000215 0.000247 0.07504</pose>
          <velocity>0.032341 0.001049 -0.001878 -0.007538 -0.015191 0.021148</velocity>
          <acceleration>26.3705 -11.7762 2.96638 2.92772 -1.00307 -3.12219</acceleration>
          <wrench>58.0751 -25.9345 6.5328 0 -0 0</wrench>
        </link>
        <link name='wam/wrist_palm_link'>
          <pose>-0.005448 -0.000528 1.19593 -0.000255 -0.000877 0.075012</pose>
          <velocity>-0.260952 -0.010968 -0.044227 0.064149 -0.911964 -0.002716</velocity>
          <acceleration>-4.36951 -0.120818 11.522 2.27107 -1.07499 -0.039541</acceleration>
          <wrench>-0.362111 -0.010012 0.954852 0 -0 0</wrench>
        </link>
        <link name='wam/wrist_pitch_link'>
          <pose>-0.005448 -0.000531 1.19593 -1.57105 -0.000882 0.075007</pose>
          <velocity>-0.260946 -0.011166 -0.044209 0.06387 -0.911645 -0.002775</velocity>
          <acceleration>-7.0081 -1.30612 11.6656 2.00109 0.97722 -1.54893</acceleration>
          <wrench>-3.63002 -0.676537 6.0425 0 -0 0</wrench>
        </link>
        <link name='wam/wrist_yaw_link'>
          <pose>-0.005447 -0.000535 1.19593 -0.000264 -0.000877 0.075005</pose>
          <velocity>-0.260933 -0.011539 -0.044266 0.06555 -0.949588 -0.002677</velocity>
          <acceleration>-9.10951 -3.10536 11.3142 0.14939 0.435655 -2.4902</acceleration>
          <wrench>-9.59923 -3.2723 11.9224 0 -0 0</wrench>
        </link>
      </model>
      <model name='suv'>
        <pose>5.00922 0.065667 -0.005888 -0.032094 -0.000901 -1.57221</pose>
        <scale>1 1 1</scale>
        <link name='link'>
          <pose>5.00922 0.065667 -0.005888 -0.032094 -0.000901 -1.57221</pose>
          <velocity>0 0 0 0 -0 0</velocity>
          <acceleration>0 0 0 0 -0 0</acceleration>
          <wrench>0 0 0 0 -0 0</wrench>
        </link>
      </model>
      <light name='sun'>
        <pose>0 0 10 0 -0 0</pose>
      </light>
    </state>
    <gui fullscreen='0'>
      <camera name='user_camera'>
        <pose>-5.8751 -33.9113 15.1394 0 0.365798 1.32998</pose>
        <view_controller>orbit</view_controller>
        <projection_type>perspective</projection_type>
      </camera>
    </gui>
    <audio>
      <device>default</device>
    </audio>
    <model name='mrobot'>
      <link name='wam/base_link'>
        <inertial>
          <pose>0 0 0 0 -0 0</pose>
          <mass>1000</mass>
          <inertia>
            <ixx>0.1</ixx>
            <ixy>0</ixy>
            <ixz>0</ixz>
            <iyy>0.1</iyy>
            <iyz>0</iyz>
            <izz>0.1</izz>
          </inertia>
        </inertial>
        <collision name='wam/base_link_collision'>
          <pose>0 0 0 0 -0 0</pose>
          <geometry>
            <mesh>
              <scale>1 1 1</scale>
              <uri>/home/robotlab/ws_gazebo_moveit/src/Barrett-7dof-WAM-arm-gazebo-moveit/barrett_model/models/sw_meshes/base_link_convex.dae</uri>
            </mesh>
          </geometry>
          <max_contacts>10</max_contacts>
          <surface>
            <contact>
              <ode/>
            </contact>
            <bounce/>
            <friction>
              <torsional>
                <ode/>
              </torsional>
              <ode/>
            </friction>
          </surface>
        </collision>
        <visual name='wam/base_link_visual'>
          <pose>0 0 0 0 -0 0</pose>
          <geometry>
            <mesh>
              <scale>1 1 1</scale>
              <uri>/home/robotlab/ws_gazebo_moveit/src/Barrett-7dof-WAM-arm-gazebo-moveit/barrett_model/models/sw_meshes/base_link_fine.stl</uri>
            </mesh>
          </geometry>
        </visual>
        <self_collide>0</self_collide>
        <enable_wind>0</enable_wind>
        <kinematic>0</kinematic>
      </link>
      <joint name='wam/base_yaw_joint' type='revolute'>
        <pose relative_to='wam/base_link'>0 0 0.346 0 -0 0</pose>
        <parent>wam/base_link</parent>
        <child>wam/shoulder_yaw_link</child>
        <axis>
          <xyz>0 0 1</xyz>
          <limit>
            <lower>-2.60002</lower>
            <upper>2.60002</upper>
            <effort>60</effort>
            <velocity>2</velocity>
          </limit>
          <dynamics>
            <damping>1.98</damping>
            <friction>0</friction>
            <spring_reference>0</spring_reference>
            <spring_stiffness>0</spring_stiffness>
          </dynamics>
        </axis>
        <physics>
          <provide_feedback>1</provide_feedback>
          <ode>
            <implicit_spring_damper>1</implicit_spring_damper>
            <cfm_damping>1</cfm_damping>
            <limit>
              <cfm>0</cfm>
              <erp>0.2</erp>
            </limit>
            <provide_feedback>1</provide_feedback>
          </ode>
        </physics>
      </joint>
      <link name='wam/shoulder_yaw_link'>
        <pose relative_to='wam/base_yaw_joint'>0 0 0 0 -0 0</pose>
        <inertial>
          <pose>-0.004434 -0.000665 -0.128904 0 -0 0</pose>
          <mass>5</mass>
          <inertia>
            <ixx>0.13488</ixx>
            <ixy>-0.00012485</ixy>
            <ixz>0.00213041</ixz>
            <iyy>0.0904633</iyy>
            <iyz>-0.00068555</iyz>
            <izz>0.113284</izz>
          </inertia>
        </inertial>
        <collision name='wam/shoulder_yaw_link_collision'>
          <pose>0 0 0 0 -0 0</pose>
          <geometry>
            <mesh>
              <scale>1 1 1</scale>
              <uri>/home/robotlab/ws_gazebo_moveit/src/Barrett-7dof-WAM-arm-gazebo-moveit/barrett_model/models/sw_meshes/shoulder_link_convex_decomposition.dae</uri>
            </mesh>
          </geometry>
          <max_contacts>10</max_contacts>
          <surface>
            <contact>
              <ode/>
            </contact>
            <bounce/>
            <friction>
              <torsional>
                <ode/>
              </torsional>
              <ode/>
            </friction>
          </surface>
        </collision>
        <visual name='wam/shoulder_yaw_link_visual'>
          <pose>0 0 0 0 -0 0</pose>
          <geometry>
            <mesh>
              <scale>1 1 1</scale>
              <uri>/home/robotlab/ws_gazebo_moveit/src/Barrett-7dof-WAM-arm-gazebo-moveit/barrett_model/models/sw_meshes/shoulder_link_fine.stl</uri>
            </mesh>
          </geometry>
        </visual>
        <self_collide>0</self_collide>
        <enable_wind>0</enable_wind>
        <kinematic>0</kinematic>
      </link>
      <joint name='wam/shoulder_pitch_joint' type='revolute'>
        <pose relative_to='wam/shoulder_yaw_link'>0 0 0 -1.5708 0 0</pose>
        <parent>wam/shoulder_yaw_link</parent>
        <child>wam/shoulder_pitch_link</child>
        <axis>
          <xyz>0 0 1</xyz>
          <limit>
            <lower>-1.985</lower>
            <upper>1.985</upper>
            <effort>60</effort>
            <velocity>2</velocity>
          </limit>
          <dynamics>
            <damping>0.55</damping>
            <friction>0</friction>
            <spring_reference>0</spring_reference>
            <spring_stiffness>0</spring_stiffness>
          </dynamics>
        </axis>
        <physics>
          <provide_feedback>1</provide_feedback>
          <ode>
            <implicit_spring_damper>1</implicit_spring_damper>
            <cfm_damping>1</cfm_damping>
            <limit>
              <cfm>0</cfm>
              <erp>0.2</erp>
            </limit>
            <provide_feedback>1</provide_feedback>
          </ode>
        </physics>
      </joint>
      <link name='wam/shoulder_pitch_link'>
        <pose relative_to='wam/shoulder_pitch_joint'>0 0 0 0 -0 0</pose>
        <inertial>
          <pose>-0.00237 -0.015421 0.031056 0 -0 0</pose>
          <mass>3.87494</mass>
          <inertia>
            <ixx>0.0214096</ixx>
            <ixy>-2.461e-05</ixy>
            <ixz>0.00027172</ixz>
            <iyy>0.0155891</iyy>
            <iyz>0.0018192</iyz>
            <izz>0.0137787</izz>
          </inertia>
        </inertial>
        <collision name='wam/shoulder_pitch_link_collision'>
          <pose>0 0 0 0 -0 0</pose>
          <geometry>
            <mesh>
              <scale>1 1 1</scale>
              <uri>/home/robotlab/ws_gazebo_moveit/src/Barrett-7dof-WAM-arm-gazebo-moveit/barrett_model/models/sw_meshes/shoulder_pitch_link_convex.dae</uri>
            </mesh>
          </geometry>
          <max_contacts>10</max_contacts>
          <surface>
            <contact>
              <ode/>
            </contact>
            <bounce/>
            <friction>
              <torsional>
                <ode/>
              </torsional>
              <ode/>
            </friction>
          </surface>
        </collision>
        <visual name='wam/shoulder_pitch_link_visual'>
          <pose>0 0 0 0 -0 0</pose>
          <geometry>
            <mesh>
              <scale>1 1 1</scale>
              <uri>/home/robotlab/ws_gazebo_moveit/src/Barrett-7dof-WAM-arm-gazebo-moveit/barrett_model/models/sw_meshes/shoulder_pitch_link_fine.stl</uri>
            </mesh>
          </geometry>
        </visual>
        <self_collide>0</self_collide>
        <enable_wind>0</enable_wind>
        <kinematic>0</kinematic>
      </link>
      <joint name='wam/shoulder_yaw_joint' type='revolute'>
        <pose relative_to='wam/shoulder_pitch_link'>0 0 0 1.5708 -0 0</pose>
        <parent>wam/shoulder_pitch_link</parent>
        <child>wam/upper_arm_link</child>
        <axis>
          <xyz>0 0 1</xyz>
          <limit>
            <lower>-2.8</lower>
            <upper>2.8</upper>
            <effort>45</effort>
            <velocity>2</velocity>
          </limit>
          <dynamics>
            <damping>1.65</damping>
            <friction>0</friction>
            <spring_reference>0</spring_reference>
            <spring_stiffness>0</spring_stiffness>
          </dynamics>
        </axis>
        <physics>
          <provide_feedback>1</provide_feedback>
          <ode>
            <implicit_spring_damper>1</implicit_spring_damper>
            <cfm_damping>1</cfm_damping>
            <limit>
              <cfm>0</cfm>
              <erp>0.2</erp>
            </limit>
            <provide_feedback>1</provide_feedback>
          </ode>
        </physics>
      </joint>
      <link name='wam/upper_arm_link'>
        <pose relative_to='wam/shoulder_yaw_joint'>0 0 0 0 -0 0</pose>
        <inertial>
          <pose>0.006833 3.3e-05 0.392492 0 -0 0</pose>
          <mass>2.20228</mass>
          <inertia>
            <ixx>0.0591108</ixx>
            <ixy>-7.38e-06</ixy>
            <ixz>-0.00249612</ixz>
            <iyy>0.0592704</iyy>
            <iyz>1.767e-05</iyz>
            <izz>0.0032455</izz>
          </inertia>
        </inertial>
        <collision name='wam/upper_arm_link_collision'>
          <pose>0 0 0 0 -0 0</pose>
          <geometry>
            <mesh>
              <scale>1 1 1</scale>
              <uri>/home/robotlab/ws_gazebo_moveit/src/Barrett-7dof-WAM-arm-gazebo-moveit/barrett_model/models/sw_meshes/upper_arm_link_convex_decomposition.dae</uri>
            </mesh>
          </geometry>
          <max_contacts>10</max_contacts>
          <surface>
            <contact>
              <ode/>
            </contact>
            <bounce/>
            <friction>
              <torsional>
                <ode/>
              </torsional>
              <ode/>
            </friction>
          </surface>
        </collision>
        <visual name='wam/upper_arm_link_visual'>
          <pose>0 0 0 0 -0 0</pose>
          <geometry>
            <mesh>
              <scale>1 1 1</scale>
              <uri>/home/robotlab/ws_gazebo_moveit/src/Barrett-7dof-WAM-arm-gazebo-moveit/barrett_model/models/sw_meshes/upper_arm_link_fine.stl</uri>
            </mesh>
          </geometry>
        </visual>
        <self_collide>0</self_collide>
        <enable_wind>0</enable_wind>
        <kinematic>0</kinematic>
      </link>
      <joint name='wam/elbow_pitch_joint' type='revolute'>
        <pose relative_to='wam/upper_arm_link'>0.045 0 0.55 -1.5708 0 0</pose>
        <parent>wam/upper_arm_link</parent>
        <child>wam/forearm_link</child>
        <axis>
          <xyz>0 0 1</xyz>
          <limit>
            <lower>-0.900014</lower>
            <upper>3.14159</upper>
            <effort>30</effort>
            <velocity>2</velocity>
          </limit>
          <dynamics>
            <damping>0.88</damping>
            <friction>0</friction>
            <spring_reference>0</spring_reference>
            <spring_stiffness>0</spring_stiffness>
          </dynamics>
        </axis>
        <physics>
          <provide_feedback>1</provide_feedback>
          <ode>
            <implicit_spring_damper>1</implicit_spring_damper>
            <cfm_damping>1</cfm_damping>
            <limit>
              <cfm>0</cfm>
              <erp>0.2</erp>
            </limit>
            <provide_feedback>1</provide_feedback>
          </ode>
        </physics>
      </joint>
      <link name='wam/forearm_link'>
        <pose relative_to='wam/elbow_pitch_joint'>0 0 0 0 -0 0</pose>
        <inertial>
          <pose>-0.040015 -0.142717 -0.000229 0 -0 0</pose>
          <mass>0.500168</mass>
          <inertia>
            <ixx>0.0149167</ixx>
            <ixy>0.00150604</ixy>
            <ixz>1.741e-05</ixz>
            <iyy>0.00294463</iyy>
            <iyz>2.109e-05</iyz>
            <izz>0.0148299</izz>
          </inertia>
        </inertial>
        <collision name='wam/forearm_link_collision'>
          <pose>0 0 0 0 -0 0</pose>
          <geometry>
            <mesh>
              <scale>1 1 1</scale>
              <uri>/home/robotlab/ws_gazebo_moveit/src/Barrett-7dof-WAM-arm-gazebo-moveit/barrett_model/models/sw_meshes/elbow_link_convex.dae</uri>
            </mesh>
          </geometry>
          <max_contacts>10</max_contacts>
          <surface>
            <contact>
              <ode/>
            </contact>
            <bounce/>
            <friction>
              <torsional>
                <ode/>
              </torsional>
              <ode/>
            </friction>
          </surface>
        </collision>
        <collision name='wam/forearm_link_collision_1'>
          <pose>-0.045 -0.073 0 1.5708 -0 0</pose>
          <geometry>
            <mesh>
              <scale>1 1 1</scale>
              <uri>/home/robotlab/ws_gazebo_moveit/src/Barrett-7dof-WAM-arm-gazebo-moveit/barrett_model/models/sw_meshes/forearm_link_convex_decomposition.dae</uri>
            </mesh>
          </geometry>
          <max_contacts>10</max_contacts>
          <surface>
            <contact>
              <ode/>
            </contact>
            <bounce/>
            <friction>
              <torsional>
                <ode/>
              </torsional>
              <ode/>
            </friction>
          </surface>
        </collision>
        <visual name='wam/forearm_link_visual'>
          <pose>0 0 0 0 -0 0</pose>
          <geometry>
            <mesh>
              <scale>1 1 1</scale>
              <uri>/home/robotlab/ws_gazebo_moveit/src/Barrett-7dof-WAM-arm-gazebo-moveit/barrett_model/models/sw_meshes/elbow_link_fine.stl</uri>
            </mesh>
          </geometry>
        </visual>
        <visual name='wam/forearm_link_visual_1'>
          <pose>-0.045 -0.073 0 1.5708 -0 0</pose>
          <geometry>
            <mesh>
              <scale>1 1 1</scale>
              <uri>/home/robotlab/ws_gazebo_moveit/src/Barrett-7dof-WAM-arm-gazebo-moveit/barrett_model/models/sw_meshes/forearm_link_fine.stl</uri>
            </mesh>
          </geometry>
        </visual>
        <self_collide>0</self_collide>
        <enable_wind>0</enable_wind>
        <kinematic>0</kinematic>
      </link>
      <joint name='wam/wrist_yaw_joint' type='revolute'>
        <pose relative_to='wam/forearm_link'>-0.045 -0.3 0 1.5708 -0 0</pose>
        <parent>wam/forearm_link</parent>
        <child>wam/wrist_yaw_link</child>
        <axis>
          <xyz>0 0 1</xyz>
          <limit>
            <lower>-4.55</lower>
            <upper>1.25</upper>
            <effort>10</effort>
            <velocity>2</velocity>
          </limit>
          <dynamics>
            <damping>0.55</damping>
            <friction>0</friction>
            <spring_reference>0</spring_reference>
            <spring_stiffness>0</spring_stiffness>
          </dynamics>
        </axis>
        <physics>
          <provide_feedback>1</provide_feedback>
          <ode>
            <implicit_spring_damper>1</implicit_spring_damper>
            <cfm_damping>1</cfm_damping>
            <limit>
              <cfm>0</cfm>
              <erp>0.2</erp>
            </limit>
            <provide_feedback>1</provide_feedback>
          </ode>
        </physics>
      </joint>
      <link name='wam/wrist_yaw_link'>
        <pose relative_to='wam/wrist_yaw_joint'>0 0 0 0 -0 0</pose>
        <inertial>
          <pose>8.9e-05 0.004358 -0.005112 0 -0 0</pose>
          <mass>1.05376</mass>
          <inertia>
            <ixx>5.029e-05</ixx>
            <ixy>2e-07</ixy>
            <ixz>7.582e-05</ixz>
            <iyy>7.582e-05</iyy>
            <iyz>-3.59e-06</iyz>
            <izz>6.27e-05</izz>
          </inertia>
        </inertial>
        <collision name='wam/wrist_yaw_link_collision'>
          <pose>0 0 0 0 -0 0</pose>
          <geometry>
            <mesh>
              <scale>1 1 1</scale>
              <uri>/home/robotlab/ws_gazebo_moveit/src/Barrett-7dof-WAM-arm-gazebo-moveit/barrett_model/models/sw_meshes/wrist_yaw_link_convex_decomposition.dae</uri>
            </mesh>
          </geometry>
          <max_contacts>10</max_contacts>
          <surface>
            <contact>
              <ode/>
            </contact>
            <bounce/>
            <friction>
              <torsional>
                <ode/>
              </torsional>
              <ode/>
            </friction>
          </surface>
        </collision>
        <visual name='wam/wrist_yaw_link_visual'>
          <pose>0 0 0 0 -0 0</pose>
          <geometry>
            <mesh>
              <scale>1 1 1</scale>
              <uri>/home/robotlab/ws_gazebo_moveit/src/Barrett-7dof-WAM-arm-gazebo-moveit/barrett_model/models/sw_meshes/wrist_yaw_link_fine.stl</uri>
            </mesh>
          </geometry>
        </visual>
        <self_collide>0</self_collide>
        <enable_wind>0</enable_wind>
        <kinematic>0</kinematic>
      </link>
      <joint name='wam/wrist_pitch_joint' type='revolute'>
        <pose relative_to='wam/wrist_yaw_link'>0 0 0 -1.5708 0 0</pose>
        <parent>wam/wrist_yaw_link</parent>
        <child>wam/wrist_pitch_link</child>
        <axis>
          <xyz>0 0 1</xyz>
          <limit>
            <lower>-1.5708</lower>
            <upper>1.5708</upper>
            <effort>10</effort>
            <velocity>2</velocity>
          </limit>
          <dynamics>
            <damping>0.11</damping>
            <friction>0</friction>
            <spring_reference>0</spring_reference>
            <spring_stiffness>0</spring_stiffness>
          </dynamics>
        </axis>
        <physics>
          <provide_feedback>1</provide_feedback>
          <ode>
            <implicit_spring_damper>1</implicit_spring_damper>
            <cfm_damping>1</cfm_damping>
            <limit>
              <cfm>0</cfm>
              <erp>0.2</erp>
            </limit>
            <provide_feedback>1</provide_feedback>
          </ode>
        </physics>
      </joint>
      <link name='wam/wrist_pitch_link'>
        <pose relative_to='wam/wrist_pitch_joint'>0 0 0 0 -0 0</pose>
        <inertial>
          <pose>-0.000123 -0.024683 -0.017032 0 -0 0</pose>
          <mass>0.517974</mass>
          <inertia>
            <ixx>0.00055516</ixx>
            <ixy>6.1e-07</ixy>
            <ixz>-7.4e-07</ixz>
            <iyy>0.00024367</iyy>
            <iyz>-4.59e-05</iyz>
            <izz>0.00045358</izz>
          </inertia>
        </inertial>
        <collision name='wam/wrist_pitch_link_collision'>
          <pose>0 0 0 0 -0 0</pose>
          <geometry>
            <mesh>
              <scale>1 1 1</scale>
              <uri>/home/robotlab/ws_gazebo_moveit/src/Barrett-7dof-WAM-arm-gazebo-moveit/barrett_model/models/sw_meshes/wrist_pitch_link_convex_decomposition.dae</uri>
            </mesh>
          </geometry>
          <max_contacts>10</max_contacts>
          <surface>
            <contact>
              <ode/>
            </contact>
            <bounce/>
            <friction>
              <torsional>
                <ode/>
              </torsional>
              <ode/>
            </friction>
          </surface>
        </collision>
        <visual name='wam/wrist_pitch_link_visual'>
          <pose>0 0 0 0 -0 0</pose>
          <geometry>
            <mesh>
              <scale>1 1 1</scale>
              <uri>/home/robotlab/ws_gazebo_moveit/src/Barrett-7dof-WAM-arm-gazebo-moveit/barrett_model/models/sw_meshes/wrist_pitch_link_fine.stl</uri>
            </mesh>
          </geometry>
        </visual>
        <self_collide>0</self_collide>
        <enable_wind>0</enable_wind>
        <kinematic>0</kinematic>
      </link>
      <joint name='wam/palm_yaw_joint' type='revolute'>
        <pose relative_to='wam/wrist_pitch_link'>0 0 0 1.5708 -0 0</pose>
        <parent>wam/wrist_pitch_link</parent>
        <child>wam/wrist_palm_link</child>
        <axis>
          <xyz>0 0 1</xyz>
          <limit>
            <lower>-3.00005</lower>
            <upper>3.00005</upper>
            <effort>10</effort>
            <velocity>2</velocity>
          </limit>
          <dynamics>
            <damping>0.11</damping>
            <friction>0</friction>
            <spring_reference>0</spring_reference>
            <spring_stiffness>0</spring_stiffness>
          </dynamics>
        </axis>
        <physics>
          <provide_feedback>1</provide_feedback>
          <ode>
            <implicit_spring_damper>1</implicit_spring_damper>
            <cfm_damping>1</cfm_damping>
            <limit>
              <cfm>0</cfm>
              <erp>0.2</erp>
            </limit>
            <provide_feedback>1</provide_feedback>
          </ode>
        </physics>
      </joint>
      <link name='wam/wrist_palm_link'>
        <pose relative_to='wam/palm_yaw_joint'>0 0 0 0 -0 0</pose>
        <inertial>
          <pose>-1e-06 0 0.055007 0 -0 0</pose>
          <mass>0.0828723</mass>
          <inertia>
            <ixx>0.00398997</ixx>
            <ixy>0</ixy>
            <ixz>6.48921e-09</ixz>
            <iyy>0.000705906</iyy>
            <iyz>0</iyz>
            <izz>0.00398787</izz>
          </inertia>
        </inertial>
        <collision name='wam/wrist_palm_link_collision'>
          <pose>0 0 0 0 -0 0</pose>
          <geometry>
            <mesh>
              <scale>1 1 1</scale>
              <uri>/home/robotlab/ws_gazebo_moveit/src/Barrett-7dof-WAM-arm-gazebo-moveit/barrett_model/models/sw_meshes/wrist_palm_link_convex.dae</uri>
            </mesh>
          </geometry>
          <max_contacts>10</max_contacts>
          <surface>
            <contact>
              <ode/>
            </contact>
            <bounce/>
            <friction>
              <torsional>
                <ode/>
              </torsional>
              <ode/>
            </friction>
          </surface>
        </collision>
        <collision name='wam/wrist_palm_link_fixed_joint_lump__camera_link_collision_1'>
          <pose>-0.011 0 0.114 0 -0 0</pose>
          <geometry>
            <box>
              <size>0.07271 0.27794 0.073</size>
            </box>
          </geometry>
          <surface>
            <contact>
              <ode/>
            </contact>
            <friction>
              <ode/>
              <torsional>
                <ode/>
              </torsional>
            </friction>
            <bounce/>
          </surface>
          <max_contacts>10</max_contacts>
        </collision>
        <visual name='wam/wrist_palm_link_visual'>
          <pose>0 0 0 0 -0 0</pose>
          <geometry>
            <mesh>
              <scale>1 1 1</scale>
              <uri>/home/robotlab/ws_gazebo_moveit/src/Barrett-7dof-WAM-arm-gazebo-moveit/barrett_model/models/sw_meshes/wrist_palm_link_fine.stl</uri>
            </mesh>
          </geometry>
        </visual>
        <visual name='wam/wrist_palm_link_fixed_joint_lump__camera_link_visual_1'>
          <pose>-0.011 0 0.114 0 -0 1.5708</pose>
          <geometry>
            <mesh>
              <scale>1 1 1</scale>
              <uri>/home/robotlab/ws_gazebo_moveit/src/Barrett-7dof-WAM-arm-gazebo-moveit/barrett_model/models/kinect.dae</uri>
            </mesh>
          </geometry>
          <material>
            <script>
              <name>Gazebo/Black</name>
              <uri>file://media/materials/scripts/gazebo.material</uri>
            </script>
          </material>
        </visual>
        <sensor name='camera' type='depth'>
          <always_on>1</always_on>
          <update_rate>30</update_rate>
          <camera>
            <horizontal_fov>1.0472</horizontal_fov>
            <image>
              <format>B8G8R8</format>
              <width>640</width>
              <height>480</height>
            </image>
            <clip>
              <near>0.05</near>
              <far>8</far>
            </clip>
          </camera>
          <plugin name='kinect_camera_controller' filename='libgazebo_ros_openni_kinect.so'>
            <cameraName>/</cameraName>
            <alwaysOn>1</alwaysOn>
            <updateRate>30</updateRate>
            <imageTopicName>rgb/image_raw</imageTopicName>
            <depthImageTopicName>/depth_to_rgb/image_raw</depthImageTopicName>
            <pointCloudTopicName>depth/points</pointCloudTopicName>
            <cameraInfoTopicName>rgb/camera_info</cameraInfoTopicName>
            <depthImageCameraInfoTopicName>depth/camera_info</depthImageCameraInfoTopicName>
            <frameName>camera_depth_optical_frame</frameName>
            <baseline>0.1</baseline>
            <distortion_k1>0.0</distortion_k1>
            <distortion_k2>0.0</distortion_k2>
            <distortion_k3>0.0</distortion_k3>
            <distortion_t1>0.0</distortion_t1>
            <distortion_t2>0.0</distortion_t2>
            <pointCloudCutoff>0.4</pointCloudCutoff>
            <robotNamespace>/</robotNamespace>
          </plugin>
          <pose>-0.011 0 0.114 0 -0 0</pose>
        </sensor>
        <self_collide>0</self_collide>
        <enable_wind>0</enable_wind>
        <kinematic>0</kinematic>
      </link>
      <static>0</static>
      <plugin name='gazebo_ros_control' filename='libgazebo_ros_control.so'>
        <robotNamespace>/arm</robotNamespace>
        <legacyModeNS>1</legacyModeNS>
      </plugin>
      <pose>0 0 0 0 -0 0</pose>
    </model>
    <model name='suv'>
      <static>1</static>
      <link name='link'>
        <collision name='collision'>
          <pose>0 0 0 0 0 -1.5708</pose>
          <geometry>
            <mesh>
              <scale>0.06 0.06 0.06</scale>
              <uri>model://suv/meshes/suv.obj</uri>
            </mesh>
          </geometry>
          <max_contacts>10</max_contacts>
          <surface>
            <contact>
              <ode/>
            </contact>
            <bounce/>
            <friction>
              <torsional>
                <ode/>
              </torsional>
              <ode/>
            </friction>
          </surface>
        </collision>
        <visual name='visual'>
          <pose>0 0 0 0 0 -1.5708</pose>
          <geometry>
            <mesh>
              <scale>0.06 0.06 0.06</scale>
              <uri>model://suv/meshes/suv.obj</uri>
            </mesh>
          </geometry>
        </visual>
        <self_collide>0</self_collide>
        <enable_wind>0</enable_wind>
        <kinematic>0</kinematic>
      </link>
      <pose>4.8222 0.202258 0 0 -0 0</pose>
    </model>
  </world>
</sdf>
