<?xml version="1.0" ?>
<!-- =================================================================================== -->
<!-- |    This document was autogenerated by xacro from /home/robotlab/ws_gazebo_moveit/src/Barrett-7dof-WAM-arm-gazebo-moveit/barrett_model/robots/mobile_7dof_wam_kinectv1.urdf.xacro | -->
<!-- |    EDITING THIS FILE BY HAND IS NOT RECOMMENDED                                 | -->
<!-- =================================================================================== -->
<!-- =================================================================================== -->
<!-- |    This document was autogenerated by xacro from wam_7dof_wam_bhand.urdf.xacro  | -->
<!-- |    EDITING THIS FILE BY HAND IS NOT RECOMMENDED                                 | -->
<!-- =================================================================================== -->
<robot name="wam" xmlns:controller="http://playerstage.sourceforge.net/gazebo/xmlschema/#controller">
    <material name="WAMGrey">
        <color rgba="0.7 0.7 0.7 1.0" />
    </material>
    <!-- Defining the colors used in this robot -->
    <!--material name="Black">
        <color rgba="0 0 0 1"/>
    </material>

    <material name="White">
        <color rgba="1 1 1 1"/>
    </material>

    <material name="Blue">
        <color rgba="0 0 1 1"/>
    </material>

    <material name="Red">
        <color rgba="1 0 0 1"/>
    </material -->
    <!-- caster position to center.  fabo:0.2     -->
    <link name="base_footprint">
        <visual>
            <origin rpy="0 0 0" xyz="0 0 0" />
            <geometry>
                <box size="0.001 0.001 0.001" />
            </geometry>
        </visual>
    </link>
    <joint name="base_footprint_joint" type="fixed">
        <origin rpy="0 0 0" xyz="0 0 0.033" />
        <parent link="base_footprint" />
        <child link="base_link" />
    </joint>
    <!-- BASE-LINK -->
    <!--Actual body/chassis of the robot-->
    <link name="base_link">
        <cylinder_inertial_matrix h="0.005" m="0.5" r="0.13" />
        <visual>
            <origin rpy="0 0 0" xyz=" 0 0 0" />
            <geometry>
                <cylinder length="0.005" radius="0.13" />
            </geometry>
            <material name="yellow" />
        </visual>
        <collision>
            <origin rpy="0 0 0" xyz="0 0 0" />
            <geometry>
                <cylinder length="0.005" radius="0.13" />
            </geometry>
        </collision>
        <inertial>
            <mass value="0.1" />
            <origin xyz="0 0 0" rpy="0 0 0" />
            <inertia ixx="0.03" iyy="0.03" izz="0.03" ixy="0.0" ixz="0.0" iyz="0.0" />
        </inertial>
    </link>
    <gazebo reference="base_link">
        <material>Gazebo/Blue</material>
        <plugin name="gazebo_ros_control" filename="libgazebo_ros_control.so">
            <robotNamespace>/</robotNamespace>
        </plugin>
    </gazebo>
    <!-- Wheel Definitions -->
    <wheel lr="right" translateY="-4" />
    <wheel lr="left" translateY="4" />
    <!-- Casters Definitions -->
    <caster fb="front" translateX="-4" />
    <caster fb="back" translateX="4" />
    <!--  plates and standoff Definitions -->
    <!-- <mrobot_standoff_2in parent="base_link" number="1" x_loc="-${standoff_x/2 + 0.03}" y_loc="-${standoff_y - 0.03}" z_loc="${plate_height/2}"/>
        <mrobot_standoff_2in parent="base_link" number="2" x_loc="-${standoff_x/2 + 0.03}" y_loc="${standoff_y - 0.03}" z_loc="${plate_height/2}"/>
        <mrobot_standoff_2in parent="base_link" number="3" x_loc="${standoff_x/2}" y_loc="-${standoff_y}" z_loc="${plate_height/2}"/>
        <mrobot_standoff_2in parent="base_link" number="4" x_loc="${standoff_x/2}" y_loc="${standoff_y}" z_loc="${plate_height/2}"/>
        <mrobot_standoff_2in parent="standoff_2in_1_link" number="5" x_loc="0" y_loc="0" z_loc="${plate_height}"/>
        <mrobot_standoff_2in parent="standoff_2in_2_link" number="6" x_loc="0" y_loc="0" z_loc="${plate_height}"/>
        <mrobot_standoff_2in parent="standoff_2in_3_link" number="7" x_loc="0" y_loc="0" z_loc="${plate_height}"/>
        <mrobot_standoff_2in parent="standoff_2in_4_link" number="8" x_loc="0" y_loc="0" z_loc="${plate_height}"/> -->
    <!--  plate Definitions -->
    <!-- <plate num="1"  parent="base_link" />
        <plate num="2"  parent="plate_1_link" /> -->
    <!-- controller -->
    <gazebo>
        <plugin filename="libgazebo_ros_diff_drive.so" name="differential_drive_controller">
            <rosDebugLevel>Debug</rosDebugLevel>
            <publishWheelTF>true</publishWheelTF>
            <robotNamespace>/</robotNamespace>
            <publishTf>1</publishTf>
            <publishWheelJointState>true</publishWheelJointState>
            <alwaysOn>true</alwaysOn>
            <updateRate>100.0</updateRate>
            <legacyMode>true</legacyMode>
            <leftJoint>base_to_wheel_left_joint</leftJoint>
            <rightJoint>base_to_wheel_right_joint</rightJoint>
            <wheelSeparation>0.26</wheelSeparation>
            <wheelDiameter>0.066</wheelDiameter>
            <broadcastTF>1</broadcastTF>
            <wheelTorque>30</wheelTorque>
            <wheelAcceleration>1.8</wheelAcceleration>
            <commandTopic>cmd_vel</commandTopic>
            <odometryFrame>odom</odometryFrame>
            <odometryTopic>odom</odometryTopic>
            <robotBaseFrame>base_footprint</robotBaseFrame>
            <legacyModeNS>true</legacyModeNS>
        </plugin>
    </gazebo>
    <joint name="wam/wam_fixed_joint" type="fixed">
        <parent link="base_footprint" />
        <child link="wam/base_link" />
        <origin rpy="0 0 0" xyz="0.0 0.0 0.03" />
    </joint>
    <gazebo reference="wam/wam_fixed_joint">
        <provideFeedback>true</provideFeedback>
        <implicitSpringDamper>true</implicitSpringDamper>
    </gazebo>
    <link name="wam/base_link">
        <inertial>
            <origin xyz="0 0 0" rpy="0 0 0" />
            <mass value="10000" />
            <inertia ixx="0.1" ixy="0" ixz="0" iyy="0.1" iyz="0" izz="0.1" />
        </inertial>
        <visual>
            <material name="WAMGrey">
                <color rgba="0.7 0.7 0.7 0.0" />
            </material>
            <geometry>
                <mesh filename="package://barrett_model/models/sw_meshes/base_link_fine.stl" />
            </geometry>
        </visual>
        <collision>
            <geometry>
                <mesh filename="package://barrett_model/models/sw_meshes/base_link_convex.dae" />
            </geometry>
        </collision>
    </link>
    <joint name="wam/base_yaw_joint" type="revolute">
        <parent link="wam/base_link" />
        <child link="wam/shoulder_yaw_link" />
        <origin rpy="0 0 0" xyz="0 0 0.346" />
        <axis xyz="0 0 1" />
        <limit effort="60" lower="-2.6000169867" upper="2.6000169867" velocity="2.0" />
        <dynamics damping="1.98" friction="0" />
    </joint>
    <gazebo reference="wam/base_yaw_joint">
        <provideFeedback>true</provideFeedback>
        <implicitSpringDamper>true</implicitSpringDamper>
        <!--<kp>0.0</kp>[> CFM <]-->
        <!--<kd>0.0</kd>[> ERP <]-->
        <!--<cfmDamping>true</cfmDamping>-->
        <!--<dynamics damping="5.5" friction="1"/>-->
    </gazebo>
    <link name="wam/shoulder_yaw_link">
        <inertial>
            <origin xyz="-.00443422 -.00066489 -0.1289039 " rpy="0 0 0" />
            <mass value="5.0" />
            <inertia ixx=".13488033" ixy="-0.00012485" ixz="0.00213041" iyy=".09046330" iyz="-.00068555" izz=".11328369" />
        </inertial>
        <visual>
            <material name="WAMGrey">
                <color rgba="0.7 0.7 0.7 1.0" />
            </material>
            <geometry>
                <mesh filename="package://barrett_model/models/sw_meshes/shoulder_link_fine.stl" />
            </geometry>
        </visual>
        <collision>
            <geometry>
                <mesh filename="package://barrett_model/models/sw_meshes/shoulder_link_convex_decomposition.dae" />
            </geometry>
        </collision>
    </link>
    <joint name="wam/shoulder_pitch_joint" type="revolute">
        <parent link="wam/shoulder_yaw_link" />
        <child link="wam/shoulder_pitch_link" />
        <origin rpy="-1.57079632679 0 0" xyz="0 0 0" />
        <axis xyz="0 0 1" />
        <limit effort="60" lower="-1.98499786488" upper="1.98499786488" velocity="2.0" />
        <dynamics damping="0.55" friction="0" />
    </joint>
    <gazebo reference="wam/shoulder_pitch_joint">
        <provideFeedback>true</provideFeedback>
        <implicitSpringDamper>true</implicitSpringDamper>
        <!--<kp>0.0</kp>[> CFM <]-->
        <!--<kd>0.0</kd>[> ERP <]-->
        <!--<cfmDamping>true</cfmDamping>-->
        <!--<dynamics damping="5.5" friction="1"/>-->
    </gazebo>
    <link name="wam/shoulder_pitch_link">
        <visual>
            <material name="WAMGrey">
                <color rgba="0.7 0.7 0.7 1.0" />
            </material>
            <geometry>
                <mesh filename="package://barrett_model/models/sw_meshes/shoulder_pitch_link_fine.stl" />
            </geometry>
        </visual>
        <inertial>
            <origin xyz="-.00236981 -.01542114 .03105614 " rpy="0 0 0" />
            <mass value="3.87493756" />
            <inertia ixx="0.02140958" ixy="-0.00002461" ixz="0.00027172" iyy="0.015589060" iyz="0.0018192" izz="0.01377875" />
        </inertial>
        <collision>
            <geometry>
                <mesh filename="package://barrett_model/models/sw_meshes/shoulder_pitch_link_convex.dae" />
            </geometry>
        </collision>
    </link>
    <joint name="wam/shoulder_yaw_joint" type="revolute">
        <parent link="wam/shoulder_pitch_link" />
        <child link="wam/upper_arm_link" />
        <origin rpy="1.57079632679 0 0" xyz="0 0 0" />
        <axis xyz="0 0 1" />
        <!-- <limit effort="45" lower="-2.79999681239" upper="2.79999681239" velocity="2.0"/> -->
        <limit effort="45" lower="-3.9999681239" upper="3.79999681239" velocity="2.0" />
        <!-- this is joint 3 -->
        <dynamics damping="1.65" friction="0" />
    </joint>
    <gazebo reference="wam/shoulder_yaw_joint">
        <provideFeedback>true</provideFeedback>
        <implicitSpringDamper>true</implicitSpringDamper>
        <!--<kp>0.0</kp>[> CFM <]-->
        <!--<kd>0.0</kd>[> ERP <]-->
        <!--<cfmDamping>true</cfmDamping>-->
        <!--<dynamics damping="5.5" friction="1"/>-->
    </gazebo>
    <link name="wam/upper_arm_link">
        <inertial>
            <origin xyz="0.00683258580000000 0.000033090000000 0.392492300000000" rpy="0 0 0" />
            <mass value="2.20228141" />
            <inertia ixx=".05911077" ixy="-0.00000738" ixz="-0.00249612" iyy="0.05927043" iyz="0.00001767" izz="0.0032455" />
        </inertial>
        <visual>
            <material name="WAMGrey">
                <color rgba="0.7 0.7 0.7 1.0" />
            </material>
            <geometry>
                <mesh filename="package://barrett_model/models/sw_meshes/upper_arm_link_fine.stl" />
            </geometry>
        </visual>
        <collision>
            <geometry>
                <mesh filename="package://barrett_model/models/sw_meshes/upper_arm_link_convex_decomposition.dae" />
            </geometry>
        </collision>
    </link>
    <joint name="wam/elbow_pitch_joint" type="revolute">
        <parent link="wam/upper_arm_link" />
        <child link="wam/forearm_link" />
        <origin rpy="-1.57079632679 0 0" xyz="0.045 0 0.55" />
        <axis xyz="0 0 1" />
        <limit effort="30" lower="-0.900013935376" upper="3.14159265359" velocity="2.00" />
        <dynamics damping="0.88" friction="0" />
    </joint>
    <gazebo reference="wam/elbow_pitch_joint">
        <provideFeedback>true</provideFeedback>
        <implicitSpringDamper>true</implicitSpringDamper>
        <!--<kp>0.0</kp>[> CFM <]-->
        <!--<kd>0.0</kd>[> ERP <]-->
        <!--<cfmDamping>true</cfmDamping>-->
        <!--<dynamics damping="5.5" friction="1"/>-->
    </gazebo>
    <link name="wam/forearm_link">
        <inertial>
            <mass value="0.50016804" />
            <origin rpy="0 0 0" xyz="-0.04001488 -.14271662 -.00022942 " />
            <inertia ixx="0.01491672" ixy="0.001506040000000" ixz="0.000017410000000" iyy="0.002944630000000" iyz="0.000021090000000" izz="0.014829880000000" />
        </inertial>
        <visual>
            <material name="WAMGrey">
                <color rgba="0.7 0.7 0.7 1.0" />
            </material>
            <geometry>
                <mesh filename="package://barrett_model/models/sw_meshes/elbow_link_fine.stl" />
            </geometry>
        </visual>
        <collision>
            <geometry>
                <mesh filename="package://barrett_model/models/sw_meshes/elbow_link_convex.dae" />
            </geometry>
        </collision>
        <visual>
            <material name="WAMGrey">
                <color rgba="0.7 0.7 0.7 1.0" />
            </material>
            <origin rpy="1.57079632679 0 0" xyz="-0.045 -0.0730 0" />
            <geometry>
                <mesh filename="package://barrett_model/models/sw_meshes/forearm_link_fine.stl" />
            </geometry>
        </visual>
        <collision>
            <origin rpy="1.57079632679 0 0" xyz="-0.045 -0.0730 0" />
            <geometry>
                <mesh filename="package://barrett_model/models/sw_meshes/forearm_link_convex_decomposition.dae" />
            </geometry>
        </collision>
    </link>
    <joint name="wam/wrist_yaw_joint" type="revolute">
        <parent link="wam/forearm_link" />
        <child link="wam/wrist_yaw_link" />
        <origin rpy="1.57079632679 0 0" xyz="-0.045 -0.3 0" />
        <axis xyz="0 0 1" />
        <!-- <limit effort="10" lower="-4.55000354678" upper="1.25000481028" velocity="2.0"/> -->
        <limit effort="10" lower="-4.55000354678" upper="2.25000481028" velocity="2.0" />
        <!-- this is joint 5 -->
        <dynamics damping="0.55" friction="0" />
    </joint>
    <gazebo reference="wam/wrist_yaw_joint">
        <provideFeedback>true</provideFeedback>
        <implicitSpringDamper>true</implicitSpringDamper>
        <!--<kp>0.0</kp>[> CFM <]-->
        <!--<kd>0.0</kd>[> ERP <]-->
        <!--<cfmDamping>true</cfmDamping>-->
        <!--<dynamics damping="5.5" friction="1"/>-->
    </gazebo>
    <link name="wam/wrist_yaw_link">
        <inertial>
            <origin xyz="0.00008921 0.00435824 -0.00511217 " rpy="0 0 0" />
            <mass value="1.05376019" />
            <inertia ixx="0.00005029" ixy="0.00000020" ixz="0.00007582" iyy="0.00007582" iyz="-0.00000359" izz="0.00006270" />
        </inertial>
        <visual>
            <material name="WAMGrey">
                <color rgba="0.7 0.7 0.7 1.0" />
            </material>
            <origin rpy="0 0 0" xyz="0 0 0" />
            <geometry>
                <mesh filename="package://barrett_model/models/sw_meshes/wrist_yaw_link_fine.stl" />
            </geometry>
        </visual>
        <collision>
            <origin rpy="0 0 0" xyz="0 0 0" />
            <geometry>
                <mesh filename="package://barrett_model/models/sw_meshes/wrist_yaw_link_convex_decomposition.dae" />
            </geometry>
        </collision>
    </link>
    <joint name="wam/wrist_pitch_joint" type="revolute">
        <parent link="wam/wrist_yaw_link" />
        <child link="wam/wrist_pitch_link" />
        <origin rpy="-1.57079632679 0 0" xyz="0 0 0" />
        <axis xyz="0 0 1" />
        <limit effort="10" lower="-1.57079632679" upper="1.57079632679" velocity="2.00" />
        <dynamics damping="0.11" friction="0" />
    </joint>
    <gazebo reference="wam/wrist_pitch_joint">
        <provideFeedback>true</provideFeedback>
        <implicitSpringDamper>true</implicitSpringDamper>
        <!--<kp>0.0</kp>[> CFM <]-->
        <!--<kd>0.0</kd>[> ERP <]-->
        <!--<cfmDamping>true</cfmDamping>-->
        <!--<dynamics damping="5.5" friction="1"/>-->
    </gazebo>
    <link name="wam/wrist_pitch_link">
        <inertial>
            <origin rpy="0 0 0" xyz="-0.00012262 -0.02468336 -0.01703194 " />
            <mass value="0.51797364" />
            <inertia ixx="0.00055516" ixy="0.00000061" ixz="-0.00000074" iyy="0.00024367" iyz="-0.00004590" izz="0.00045358" />
        </inertial>
        <visual>
            <material name="WAMGrey">
                <color rgba="0.7 0.7 0.7 1.0" />
            </material>
            <geometry>
                <mesh filename="package://barrett_model/models/sw_meshes/wrist_pitch_link_fine.stl" />
            </geometry>
        </visual>
        <collision>
            <geometry>
                <mesh filename="package://barrett_model/models/sw_meshes/wrist_pitch_link_convex_decomposition.dae" />
            </geometry>
        </collision>
    </link>
    <joint name="wam/palm_yaw_joint" type="revolute">
        <parent link="wam/wrist_pitch_link" />
        <child link="wam/wrist_palm_link" />
        <origin rpy="1.57079632679 0 0" xyz="0 0 0" />
        <axis xyz="0 0 1" />
        <limit effort="10" lower="-3.00004645125" upper="3.00004645125" velocity="2.00" />
        <!-- 2.95 is a limit taken in from 3 due to saftey and differences between arms. -->
        <dynamics damping="0.11" friction="0" />
    </joint>
    <gazebo reference="wam/palm_yaw_joint">
        <provideFeedback>true</provideFeedback>
        <implicitSpringDamper>true</implicitSpringDamper>
        <!--<kp>0.0</kp>[> CFM <]-->
        <!--<kd>0.0</kd>[> ERP <]-->
        <!--<cfmDamping>true</cfmDamping>-->
        <!--<dynamics damping="5.5" friction="1"/>-->
    </gazebo>
    <transmission name="wam/palm_yaw_trans">
        <type>transmission_interface/SimpleTransmission</type>
        <joint name="wam/palm_yaw_joint">
            <hardwareInterface>hardware_interface/VelocityJointInterface</hardwareInterface>
        </joint>
        <actuator name="wam/palm_yaw_motor">
            <mechanicalReduction>1</mechanicalReduction>
        </actuator>
    </transmission>
    <link name="wam/wrist_palm_link">
        <inertial>
            <origin rpy="0 0 0" xyz="0.0 0.0 0.055" />
            <mass value="0.08286134" />
            <inertia ixx="0.00010859" ixy="0.00000000" ixz="-0.00000000" iyy="0.00020683" iyz="-0.0000000" izz="0.00010851" />
        </inertial>
        <visual>
            <material name="WAMGrey">
                <color rgba="0.7 0.7 0.7 1.0" />
            </material>
            <origin rpy="0 0 0" xyz="0 0 0" />
            <geometry>
                <mesh filename="package://barrett_model/models/sw_meshes/wrist_palm_link_fine.stl" />
            </geometry>
        </visual>
        <collision>
            <origin rpy="0 0 0" xyz="0 0 0" />
            <geometry>
                <mesh filename="package://barrett_model/models/sw_meshes/wrist_palm_link_convex.dae" />
            </geometry>
        </collision>
    </link>
    <joint name="wam/wrist_palm_stump_joint" type="fixed">
        <parent link="wam/wrist_palm_link" />
        <child link="wam/wrist_palm_stump_link" />
        <origin rpy="0 0 0" xyz="0 0 0.06" />
    </joint>
    <link name="wam/wrist_palm_stump_link">
        <inertial>
            <mass value="0.000001" />
            <inertia ixx="0.0000001" ixy="0.0" ixz="0.0" iyy="0.0000001" iyz="0.0" izz="0.0000001" />
        </inertial>
    </link>
    <joint name="camera_rgb_joint" type="fixed">
        <origin rpy="0 0 0" xyz="0.02 -0.0125 0.07" />
        <parent link="wam/wrist_palm_stump_link" />
        <child link="camera_rgb_frame" />
    </joint>
    <link name="camera_rgb_frame" />
    <joint name="camera_rgb_optical_joint" type="fixed">
        <origin rpy="-1.5707963267948966 0 -1.5707963267948966" xyz="0 0 0" />
        <parent link="camera_rgb_frame" />
        <child link="camera_rgb_optical_frame" />
    </joint>
    <link name="camera_rgb_optical_frame" />
    <joint name="camera_joint" type="fixed">
        <origin rpy="0 0 0" xyz="-0.031 0.0125 -0.016" />
        <parent link="camera_rgb_frame" />
        <child link="camera_link" />
    </joint>
    <link name="camera_link">
        <visual>
            <origin rpy="0 0 1.5707963267948966" xyz="0 0 0" />
            <geometry>
                <mesh filename="package://barrett_model/models/kinect.dae" />
            </geometry>
        </visual>
        <collision>
            s
            <origin rpy="0 0 0" xyz="0.0 0.0 0.0" />
            <geometry>
                <box size="0.07271 0.27794 0.073" />
            </geometry>
        </collision>
        <inertial>
            <mass value="1e-5" />
            <!-- 0.564 -->
            <origin xyz="0 0 0" rpy="0 0 0" />
            <inertia ixx="0.003881243" ixy="0.0" ixz="0.0" iyy="0.000498940" iyz="0.0" izz="0.003879257" />
        </inertial>
    </link>
    <!-- The fixed joints & links below are usually published by static_transformers launched by the OpenNi launch 
         files. However, for Gazebo simulation we need them, so we add them here.
         (Hence, don't publish them additionally!) -->
    <joint name="camera_depth_joint" type="fixed">
        <origin rpy="0 0 0" xyz="0 0.025 0" />
        <parent link="camera_rgb_frame" />
        <child link="camera_depth_frame" />
    </joint>
    <link name="camera_depth_frame" />
    <joint name="camera_depth_optical_joint" type="fixed">
        <origin rpy="-1.5707963267948966 0 -1.5707963267948966" xyz="0 0 0" />
        <parent link="camera_depth_frame" />
        <child link="camera_depth_optical_frame" />
    </joint>
    <link name="camera_depth_optical_frame" />
    <gazebo reference="camera_link">
        <sensor name="camera" type="depth">
            <always_on>true</always_on>
            <update_rate>30.0</update_rate>
            <camera>
                <horizontal_fov>1.0471975511965976</horizontal_fov>
                <image>
                    <format>B8G8R8</format>
                    <width>640</width>
                    <height>480</height>
                </image>
                <clip>
                    <near>0.05</near>
                    <far>8.0</far>
                </clip>
            </camera>
            <plugin filename="libgazebo_ros_openni_kinect.so" name="kinect_camera_controller">
                <cameraName>/</cameraName>
                <alwaysOn>true</alwaysOn>
                <updateRate>30</updateRate>
                <imageTopicName>rgb/image_raw</imageTopicName>
                <depthImageTopicName>/depth_to_rgb/image_raw</depthImageTopicName>
                <pointCloudTopicName>depth/points</pointCloudTopicName>
                <cameraInfoTopicName>rgb/camera_info</cameraInfoTopicName>
                <depthImageCameraInfoTopicName>depth/camera_info</depthImageCameraInfoTopicName>
                <frameName>camera_depth_optical_frame</frameName>
                <baseline>0.1</baseline>
                <distortion_k1>0.0</distortion_k1>
                <distortion_k2>0.0</distortion_k2>
                <distortion_k3>0.0</distortion_k3>
                <distortion_t1>0.0</distortion_t1>
                <distortion_t2>0.0</distortion_t2>
                <pointCloudCutoff>0.4</pointCloudCutoff>
            </plugin>
        </sensor>
        <material>Gazebo/Black</material>
    </gazebo>
    <transmission name="wam/base_yaw_trans">
        <type>transmission_interface/SimpleTransmission</type>
        <joint name="wam/base_yaw_joint">
            <hardwareInterface>hardware_interface/PositionJointInterface</hardwareInterface>
        </joint>
        <actuator name="wam/base_yaw_motor">
            <hardwareInterface>hardware_interface/PositionJointInterface</hardwareInterface>
            <mechanicalReduction>1</mechanicalReduction>
        </actuator>
    </transmission>
    <transmission name="wam/shoulder_pitch_trans">
        <type>transmission_interface/SimpleTransmission</type>
        <joint name="wam/shoulder_pitch_joint">
            <hardwareInterface>hardware_interface/PositionJointInterface</hardwareInterface>
        </joint>
        <actuator name="wam/shoulder_pitch_motor">
            <hardwareInterface>hardware_interface/PositionJointInterface</hardwareInterface>
            <mechanicalReduction>1</mechanicalReduction>
        </actuator>
    </transmission>
    <transmission name="wam/shoulder_yaw_trans">
        <type>transmission_interface/SimpleTransmission</type>
        <joint name="wam/shoulder_yaw_joint">
            <hardwareInterface>hardware_interface/PositionJointInterface</hardwareInterface>
        </joint>
        <actuator name="wam/shoulder_yaw_motor">
            <hardwareInterface>hardware_interface/PositionJointInterface</hardwareInterface>
            <mechanicalReduction>1</mechanicalReduction>
        </actuator>
    </transmission>
    <transmission name="wam/elbow_pitch_trans">
        <type>transmission_interface/SimpleTransmission</type>
        <joint name="wam/elbow_pitch_joint">
            <hardwareInterface>hardware_interface/PositionJointInterface</hardwareInterface>
        </joint>
        <actuator name="wam/elbow_pitch_motor">
            <hardwareInterface>hardware_interface/PositionJointInterface</hardwareInterface>
            <mechanicalReduction>1</mechanicalReduction>
        </actuator>
    </transmission>
    <transmission name="wam/wrist_yaw_trans">
        <type>transmission_interface/SimpleTransmission</type>
        <joint name="wam/wrist_yaw_joint">
            <hardwareInterface>hardware_interface/PositionJointInterface</hardwareInterface>
        </joint>
        <actuator name="wam/wrist_yaw_motor">
            <hardwareInterface>hardware_interface/PositionJointInterface</hardwareInterface>
            <mechanicalReduction>1</mechanicalReduction>
        </actuator>
    </transmission>
    <transmission name="wam/wrist_pitch_trans">
        <type>transmission_interface/SimpleTransmission</type>
        <joint name="wam/wrist_pitch_joint">
            <hardwareInterface>hardware_interface/PositionJointInterface</hardwareInterface>
        </joint>
        <actuator name="wam/wrist_pitch_motor">
            <hardwareInterface>hardware_interface/PositionJointInterface</hardwareInterface>
            <mechanicalReduction>1</mechanicalReduction>
        </actuator>
    </transmission>
    <transmission name="wam/palm_yaw_trans">
        <type>transmission_interface/SimpleTransmission</type>
        <joint name="wam/palm_yaw_joint">
            <hardwareInterface>hardware_interface/PositionJointInterface</hardwareInterface>
        </joint>
        <actuator name="wam/palm_yaw_motor">
            <hardwareInterface>hardware_interface/PositionJointInterface</hardwareInterface>
            <mechanicalReduction>1</mechanicalReduction>
        </actuator>
    </transmission>
    <gazebo>
        <plugin filename="libgazebo_ros_control.so" name="gazebo_ros_control">
            <robotNamespace>/arm</robotNamespace>
            <legacyModeNS>true</legacyModeNS>
        </plugin>
    </gazebo>
</robot>

